[2024-08-09 04:53:39,033] {taskinstance.py:896} INFO - Dependencies all met for <TaskInstance: create_postgres_table.create_table 2024-08-09T04:53:37.809113+00:00 [queued]>
[2024-08-09 04:53:39,039] {taskinstance.py:896} INFO - Dependencies all met for <TaskInstance: create_postgres_table.create_table 2024-08-09T04:53:37.809113+00:00 [queued]>
[2024-08-09 04:53:39,039] {taskinstance.py:1087} INFO - 
--------------------------------------------------------------------------------
[2024-08-09 04:53:39,039] {taskinstance.py:1088} INFO - Starting attempt 1 of 2
[2024-08-09 04:53:39,039] {taskinstance.py:1089} INFO - 
--------------------------------------------------------------------------------
[2024-08-09 04:53:39,050] {taskinstance.py:1107} INFO - Executing <Task(PostgresOperator): create_table> on 2024-08-09T04:53:37.809113+00:00
[2024-08-09 04:53:39,053] {standard_task_runner.py:52} INFO - Started process 11865 to run task
[2024-08-09 04:53:39,056] {standard_task_runner.py:76} INFO - Running: ['***', 'tasks', 'run', 'create_postgres_table', 'create_table', '2024-08-09T04:53:37.809113+00:00', '--job-id', '2', '--pool', 'default_pool', '--raw', '--subdir', 'DAGS_FOLDER/database_dag.py', '--cfg-path', '/tmp/tmpdofqalrt', '--error-file', '/tmp/tmp8nk416ha']
[2024-08-09 04:53:39,058] {standard_task_runner.py:77} INFO - Job 2: Subtask create_table
[2024-08-09 04:53:39,110] {logging_mixin.py:104} INFO - Running <TaskInstance: create_postgres_table.create_table 2024-08-09T04:53:37.809113+00:00 [running]> on host a6174e1e42cd
[2024-08-09 04:53:39,168] {taskinstance.py:1302} INFO - Exporting the following env vars:
AIRFLOW_CTX_DAG_OWNER=***
AIRFLOW_CTX_DAG_ID=create_postgres_table
AIRFLOW_CTX_TASK_ID=create_table
AIRFLOW_CTX_EXECUTION_DATE=2024-08-09T04:53:37.809113+00:00
AIRFLOW_CTX_DAG_RUN_ID=manual__2024-08-09T04:53:37.809113+00:00
[2024-08-09 04:53:39,168] {postgres.py:68} INFO - Executing: 
        CREATE schema if not exists silver;
        CREATE schema if not exists gold;
        
[2024-08-09 04:53:39,176] {base.py:78} INFO - Using connection to: id: ***_conn. Host: db, Port: 5432, Schema: public, Login: ***, Password: ***, extra: {}
[2024-08-09 04:53:39,180] {taskinstance.py:1501} ERROR - Task failed with exception
Traceback (most recent call last):
  File "/home/airflow/.local/lib/python3.6/site-packages/airflow/models/taskinstance.py", line 1157, in _run_raw_task
    self._prepare_and_execute_task_with_callbacks(context, task)
  File "/home/airflow/.local/lib/python3.6/site-packages/airflow/models/taskinstance.py", line 1331, in _prepare_and_execute_task_with_callbacks
    result = self._execute_task(context, task_copy)
  File "/home/airflow/.local/lib/python3.6/site-packages/airflow/models/taskinstance.py", line 1361, in _execute_task
    result = task_copy.execute(context=context)
  File "/home/airflow/.local/lib/python3.6/site-packages/airflow/providers/postgres/operators/postgres.py", line 70, in execute
    self.hook.run(self.sql, self.autocommit, parameters=self.parameters)
  File "/home/airflow/.local/lib/python3.6/site-packages/airflow/hooks/dbapi.py", line 177, in run
    with closing(self.get_conn()) as conn:
  File "/home/airflow/.local/lib/python3.6/site-packages/airflow/providers/postgres/hooks/postgres.py", line 115, in get_conn
    self.conn = psycopg2.connect(**conn_args)
  File "/home/airflow/.local/lib/python3.6/site-packages/psycopg2/__init__.py", line 122, in connect
    conn = _connect(dsn, connection_factory=connection_factory, **kwasync)
psycopg2.OperationalError: FATAL:  database "public" does not exist

[2024-08-09 04:53:39,182] {taskinstance.py:1551} INFO - Marking task as UP_FOR_RETRY. dag_id=create_***_table, task_id=create_table, execution_date=20240809T045337, start_date=20240809T045339, end_date=20240809T045339
[2024-08-09 04:53:39,228] {local_task_job.py:149} INFO - Task exited with return code 1
