[2024-08-09 18:44:43,786] {taskinstance.py:896} INFO - Dependencies all met for <TaskInstance: grillos_operations.grant_privileges 2024-08-09T00:55:00+00:00 [queued]>
[2024-08-09 18:44:43,884] {taskinstance.py:896} INFO - Dependencies all met for <TaskInstance: grillos_operations.grant_privileges 2024-08-09T00:55:00+00:00 [queued]>
[2024-08-09 18:44:43,884] {taskinstance.py:1087} INFO - 
--------------------------------------------------------------------------------
[2024-08-09 18:44:43,885] {taskinstance.py:1088} INFO - Starting attempt 1 of 2
[2024-08-09 18:44:43,885] {taskinstance.py:1089} INFO - 
--------------------------------------------------------------------------------
[2024-08-09 18:44:43,914] {taskinstance.py:1107} INFO - Executing <Task(PostgresOperator): grant_privileges> on 2024-08-09T00:55:00+00:00
[2024-08-09 18:44:43,943] {standard_task_runner.py:52} INFO - Started process 397 to run task
[2024-08-09 18:44:43,987] {standard_task_runner.py:76} INFO - Running: ['***', 'tasks', 'run', 'grillos_operations', 'grant_privileges', '2024-08-09T00:55:00+00:00', '--job-id', '29', '--pool', 'default_pool', '--raw', '--subdir', 'DAGS_FOLDER/database_dag.py', '--cfg-path', '/tmp/tmpr59be64h', '--error-file', '/tmp/tmpe3od7d2r']
[2024-08-09 18:44:44,015] {standard_task_runner.py:77} INFO - Job 29: Subtask grant_privileges
[2024-08-09 18:44:44,395] {logging_mixin.py:104} INFO - Running <TaskInstance: grillos_operations.grant_privileges 2024-08-09T00:55:00+00:00 [running]> on host 9a7f3bfa7ef6
[2024-08-09 18:44:44,770] {taskinstance.py:1302} INFO - Exporting the following env vars:
AIRFLOW_CTX_DAG_OWNER=***
AIRFLOW_CTX_DAG_ID=grillos_operations
AIRFLOW_CTX_TASK_ID=grant_privileges
AIRFLOW_CTX_EXECUTION_DATE=2024-08-09T00:55:00+00:00
AIRFLOW_CTX_DAG_RUN_ID=scheduled__2024-08-09T00:55:00+00:00
[2024-08-09 18:44:44,771] {postgres.py:68} INFO - Executing: 
    BEGIN;
    GRANT USAGE ON SCHEMA silver TO dataengineer;
    GRANT USAGE ON SCHEMA gold TO dataengineer;
    GRANT SELECT ON ALL TABLES IN SCHEMA silver TO dataengineer;
    GRANT SELECT ON ALL TABLES IN SCHEMA gold TO dataengineer;
    ALTER DEFAULT PRIVILEGES IN SCHEMA silver GRANT SELECT ON TABLES TO postgres;
    ALTER DEFAULT PRIVILEGES IN SCHEMA gold GRANT SELECT ON TABLES TO postgres;
    COMMIT;
    
[2024-08-09 18:44:44,867] {base.py:78} INFO - Using connection to: id: ***_conn. Host: db, Port: 5432, Schema: grillos, Login: ***, Password: ***, extra: {}
[2024-08-09 18:44:44,911] {dbapi.py:204} INFO - Running statement: 
    BEGIN;
    GRANT USAGE ON SCHEMA silver TO dataengineer;
    GRANT USAGE ON SCHEMA gold TO dataengineer;
    GRANT SELECT ON ALL TABLES IN SCHEMA silver TO dataengineer;
    GRANT SELECT ON ALL TABLES IN SCHEMA gold TO dataengineer;
    ALTER DEFAULT PRIVILEGES IN SCHEMA silver GRANT SELECT ON TABLES TO ***;
    ALTER DEFAULT PRIVILEGES IN SCHEMA gold GRANT SELECT ON TABLES TO ***;
    COMMIT;
    , parameters: None
[2024-08-09 18:44:44,924] {taskinstance.py:1501} ERROR - Task failed with exception
Traceback (most recent call last):
  File "/home/airflow/.local/lib/python3.6/site-packages/airflow/models/taskinstance.py", line 1157, in _run_raw_task
    self._prepare_and_execute_task_with_callbacks(context, task)
  File "/home/airflow/.local/lib/python3.6/site-packages/airflow/models/taskinstance.py", line 1331, in _prepare_and_execute_task_with_callbacks
    result = self._execute_task(context, task_copy)
  File "/home/airflow/.local/lib/python3.6/site-packages/airflow/models/taskinstance.py", line 1361, in _execute_task
    result = task_copy.execute(context=context)
  File "/home/airflow/.local/lib/python3.6/site-packages/airflow/providers/postgres/operators/postgres.py", line 70, in execute
    self.hook.run(self.sql, self.autocommit, parameters=self.parameters)
  File "/home/airflow/.local/lib/python3.6/site-packages/airflow/hooks/dbapi.py", line 184, in run
    self._run_command(cur, sql_statement, parameters)
  File "/home/airflow/.local/lib/python3.6/site-packages/airflow/hooks/dbapi.py", line 208, in _run_command
    cur.execute(sql_statement)
psycopg2.errors.UndefinedObject: role "dataengineer" does not exist

[2024-08-09 18:44:44,936] {taskinstance.py:1551} INFO - Marking task as UP_FOR_RETRY. dag_id=grillos_operations, task_id=grant_privileges, execution_date=20240809T005500, start_date=20240809T184443, end_date=20240809T184444
[2024-08-09 18:44:45,098] {local_task_job.py:149} INFO - Task exited with return code 1
